Traceback (most recent call last):
  File "/home/ryan/.conda/envs/work3-9/lib/python3.9/site-packages/jupyter_cache/executors/utils.py", line 58, in single_nb_execution
    executenb(
  File "/home/ryan/.conda/envs/work3-9/lib/python3.9/site-packages/nbclient/client.py", line 1093, in execute
    return NotebookClient(nb=nb, resources=resources, km=km, **kwargs).execute()
  File "/home/ryan/.conda/envs/work3-9/lib/python3.9/site-packages/nbclient/util.py", line 84, in wrapped
    return just_run(coro(*args, **kwargs))
  File "/home/ryan/.conda/envs/work3-9/lib/python3.9/site-packages/nbclient/util.py", line 62, in just_run
    return loop.run_until_complete(coro)
  File "/home/ryan/.conda/envs/work3-9/lib/python3.9/asyncio/base_events.py", line 642, in run_until_complete
    return future.result()
  File "/home/ryan/.conda/envs/work3-9/lib/python3.9/site-packages/nbclient/client.py", line 559, in async_execute
    await self.async_execute_cell(
  File "/home/ryan/.conda/envs/work3-9/lib/python3.9/site-packages/nbclient/client.py", line 854, in async_execute_cell
    self._check_raise_for_error(cell, exec_reply)
  File "/home/ryan/.conda/envs/work3-9/lib/python3.9/site-packages/nbclient/client.py", line 756, in _check_raise_for_error
    raise CellExecutionError.from_cell_and_msg(cell, exec_reply_content)
nbclient.exceptions.CellExecutionError: An error occurred while executing the following cell:
------------------
fig, ax = plt.subplots(1,1)
Q = ax.quiver(0, 0, -L[0,0], -L[1,0], color='r', scale = 100, label = 'reaction force')
mark, = ax.plot(sol.y[0,0], sol.y[1,0], 's', markersize = 20, label = 'com location')
ax.plot(y.y[0], y.y[1], '.')
ax.legend()
ax.set_xlim(-1, 1)
ax.set_ylim(-0.75, 0.75)
------------------

[0;31m---------------------------------------------------------------------------[0m
[0;31mNameError[0m                                 Traceback (most recent call last)
[0;32m<ipython-input-14-f9fc5f302e44>[0m in [0;36m<module>[0;34m[0m
[1;32m      2[0m [0mQ[0m [0;34m=[0m [0max[0m[0;34m.[0m[0mquiver[0m[0;34m([0m[0;36m0[0m[0;34m,[0m [0;36m0[0m[0;34m,[0m [0;34m-[0m[0mL[0m[0;34m[[0m[0;36m0[0m[0;34m,[0m[0;36m0[0m[0;34m][0m[0;34m,[0m [0;34m-[0m[0mL[0m[0;34m[[0m[0;36m1[0m[0;34m,[0m[0;36m0[0m[0;34m][0m[0;34m,[0m [0mcolor[0m[0;34m=[0m[0;34m'r'[0m[0;34m,[0m [0mscale[0m [0;34m=[0m [0;36m100[0m[0;34m,[0m [0mlabel[0m [0;34m=[0m [0;34m'reaction force'[0m[0;34m)[0m[0;34m[0m[0;34m[0m[0m
[1;32m      3[0m [0mmark[0m[0;34m,[0m [0;34m=[0m [0max[0m[0;34m.[0m[0mplot[0m[0;34m([0m[0msol[0m[0;34m.[0m[0my[0m[0;34m[[0m[0;36m0[0m[0;34m,[0m[0;36m0[0m[0;34m][0m[0;34m,[0m [0msol[0m[0;34m.[0m[0my[0m[0;34m[[0m[0;36m1[0m[0;34m,[0m[0;36m0[0m[0;34m][0m[0;34m,[0m [0;34m's'[0m[0;34m,[0m [0mmarkersize[0m [0;34m=[0m [0;36m20[0m[0;34m,[0m [0mlabel[0m [0;34m=[0m [0;34m'com location'[0m[0;34m)[0m[0;34m[0m[0;34m[0m[0m
[0;32m----> 4[0;31m [0max[0m[0;34m.[0m[0mplot[0m[0;34m([0m[0my[0m[0;34m.[0m[0my[0m[0;34m[[0m[0;36m0[0m[0;34m][0m[0;34m,[0m [0my[0m[0;34m.[0m[0my[0m[0;34m[[0m[0;36m1[0m[0;34m][0m[0;34m,[0m [0;34m'.'[0m[0;34m)[0m[0;34m[0m[0;34m[0m[0m
[0m[1;32m      5[0m [0max[0m[0;34m.[0m[0mlegend[0m[0;34m([0m[0;34m)[0m[0;34m[0m[0;34m[0m[0m
[1;32m      6[0m [0max[0m[0;34m.[0m[0mset_xlim[0m[0;34m([0m[0;34m-[0m[0;36m1[0m[0;34m,[0m [0;36m1[0m[0;34m)[0m[0;34m[0m[0;34m[0m[0m

[0;31mNameError[0m: name 'y' is not defined
NameError: name 'y' is not defined

