Traceback (most recent call last):
  File "/home/ryan/.local/lib/python3.8/site-packages/jupyter_cache/executors/utils.py", line 51, in single_nb_execution
    executenb(
  File "/opt/miniconda3/lib/python3.8/site-packages/nbclient/client.py", line 1107, in execute
    return NotebookClient(nb=nb, resources=resources, km=km, **kwargs).execute()
  File "/opt/miniconda3/lib/python3.8/site-packages/nbclient/util.py", line 74, in wrapped
    return just_run(coro(*args, **kwargs))
  File "/opt/miniconda3/lib/python3.8/site-packages/nbclient/util.py", line 53, in just_run
    return loop.run_until_complete(coro)
  File "/opt/miniconda3/lib/python3.8/asyncio/base_events.py", line 616, in run_until_complete
    return future.result()
  File "/opt/miniconda3/lib/python3.8/site-packages/nbclient/client.py", line 553, in async_execute
    await self.async_execute_cell(
  File "/opt/miniconda3/lib/python3.8/site-packages/nbclient/client.py", line 852, in async_execute_cell
    self._check_raise_for_error(cell, exec_reply)
  File "/opt/miniconda3/lib/python3.8/site-packages/nbclient/client.py", line 760, in _check_raise_for_error
    raise CellExecutionError.from_cell_and_msg(cell, exec_reply_content)
nbclient.exceptions.CellExecutionError: An error occurred while executing the following cell:
------------------
3*k/m*np.cos(sol)*np.cos(sol)-3*g/2/l*np.sin(sol)
------------------

[0;31m---------------------------------------------------------------------------[0m
[0;31mKeyError[0m                                  Traceback (most recent call last)
[0;32m/opt/miniconda3/lib/python3.8/site-packages/scipy/optimize/optimize.py[0m in [0;36m__getattr__[0;34m(self, name)[0m
[1;32m    121[0m         [0;32mtry[0m[0;34m:[0m[0;34m[0m[0;34m[0m[0m
[0;32m--> 122[0;31m             [0;32mreturn[0m [0mself[0m[0;34m[[0m[0mname[0m[0;34m][0m[0;34m[0m[0;34m[0m[0m
[0m[1;32m    123[0m         [0;32mexcept[0m [0mKeyError[0m [0;32mas[0m [0me[0m[0;34m:[0m[0;34m[0m[0;34m[0m[0m

[0;31mKeyError[0m: 'cos'

The above exception was the direct cause of the following exception:

[0;31mAttributeError[0m                            Traceback (most recent call last)
[0;32m/opt/miniconda3/lib/python3.8/site-packages/scipy/optimize/optimize.py[0m in [0;36m__getattr__[0;34m(self, name)[0m
[1;32m    123[0m         [0;32mexcept[0m [0mKeyError[0m [0;32mas[0m [0me[0m[0;34m:[0m[0;34m[0m[0;34m[0m[0m
[0;32m--> 124[0;31m             [0;32mraise[0m [0mAttributeError[0m[0;34m([0m[0mname[0m[0;34m)[0m [0;32mfrom[0m [0me[0m[0;34m[0m[0;34m[0m[0m
[0m[1;32m    125[0m [0;34m[0m[0m

[0;31mAttributeError[0m: cos

The above exception was the direct cause of the following exception:

[0;31mTypeError[0m                                 Traceback (most recent call last)
[0;32m<ipython-input-8-62fb46986f6b>[0m in [0;36m<module>[0;34m[0m
[0;32m----> 1[0;31m [0;36m3[0m[0;34m*[0m[0mk[0m[0;34m/[0m[0mm[0m[0;34m*[0m[0mnp[0m[0;34m.[0m[0mcos[0m[0;34m([0m[0msol[0m[0;34m)[0m[0;34m*[0m[0mnp[0m[0;34m.[0m[0mcos[0m[0;34m([0m[0msol[0m[0;34m)[0m[0;34m-[0m[0;36m3[0m[0;34m*[0m[0mg[0m[0;34m/[0m[0;36m2[0m[0;34m/[0m[0ml[0m[0;34m*[0m[0mnp[0m[0;34m.[0m[0msin[0m[0;34m([0m[0msol[0m[0;34m)[0m[0;34m[0m[0;34m[0m[0m
[0m
[0;31mTypeError[0m: loop of ufunc does not support argument 0 of type OdeResult which has no callable cos method
TypeError: loop of ufunc does not support argument 0 of type OdeResult which has no callable cos method

